2025-03-09 09:35:10,196 INFO    MainThread:27324 [wandb_setup.py:_flush():67] Current SDK version is 0.19.7
2025-03-09 09:35:10,197 INFO    MainThread:27324 [wandb_setup.py:_flush():67] Configure stats pid to 27324
2025-03-09 09:35:10,198 INFO    MainThread:27324 [wandb_setup.py:_flush():67] Loading settings from C:\Users\shrey\.config\wandb\settings
2025-03-09 09:35:10,200 INFO    MainThread:27324 [wandb_setup.py:_flush():67] Loading settings from C:\Users\shrey\Desktop\ACAD\DL\DA6401_AS1\wandb\settings
2025-03-09 09:35:10,200 INFO    MainThread:27324 [wandb_setup.py:_flush():67] Loading settings from environment variables
2025-03-09 09:35:10,202 INFO    MainThread:27324 [wandb_init.py:setup_run_log_directory():647] Logging user logs to C:\Users\shrey\Desktop\ACAD\DL\DA6401_AS1\wandb\run-20250309_093510-u7epaw99\logs\debug.log
2025-03-09 09:35:10,206 INFO    MainThread:27324 [wandb_init.py:setup_run_log_directory():648] Logging internal logs to C:\Users\shrey\Desktop\ACAD\DL\DA6401_AS1\wandb\run-20250309_093510-u7epaw99\logs\debug-internal.log
2025-03-09 09:35:10,206 INFO    MainThread:27324 [wandb_init.py:init():761] calling init triggers
2025-03-09 09:35:10,206 INFO    MainThread:27324 [wandb_init.py:init():766] wandb.init called with sweep_config: {'activation': 'tanh', 'batch_size': 32, 'beta': 0.059711800453215544, 'beta1': 0.9912861793216456, 'beta2': 0.9982486894671256, 'epochs': 15, 'epsilon': 2.965663513265211e-06, 'hidden_size': 128, 'learning_rate': 0.00024056676590147424, 'loss': 'cross_entropy', 'momentum': 0.9673048381736516, 'num_layers': 5, 'optimizer': 'adam', 'weight_decay': 0, 'weight_init': 'Xavier'}
config: {'_wandb': {}}
2025-03-09 09:35:10,209 INFO    MainThread:27324 [wandb_init.py:init():784] starting backend
2025-03-09 09:35:10,210 INFO    MainThread:27324 [wandb_init.py:init():788] sending inform_init request
2025-03-09 09:35:10,297 INFO    MainThread:27324 [backend.py:_multiprocessing_setup():97] multiprocessing start_methods=spawn, using: spawn
2025-03-09 09:35:10,299 INFO    MainThread:27324 [wandb_init.py:init():803] backend started and connected
2025-03-09 09:35:10,303 INFO    MainThread:27324 [wandb_run.py:_config_callback():1261] config_cb None None {'activation': 'tanh', 'batch_size': 32, 'beta': 0.059711800453215544, 'beta1': 0.9912861793216456, 'beta2': 0.9982486894671256, 'epochs': 15, 'epsilon': 2.965663513265211e-06, 'hidden_size': 128, 'learning_rate': 0.00024056676590147424, 'loss': 'cross_entropy', 'momentum': 0.9673048381736516, 'num_layers': 5, 'optimizer': 'adam', 'weight_decay': 0, 'weight_init': 'Xavier'}
2025-03-09 09:35:10,305 INFO    MainThread:27324 [wandb_init.py:init():896] updated telemetry
2025-03-09 09:35:10,455 INFO    MainThread:27324 [wandb_init.py:init():920] communicating run to backend with 90.0 second timeout
2025-03-09 09:35:11,294 INFO    MainThread:27324 [wandb_init.py:init():995] starting run threads in backend
2025-03-09 09:35:14,907 INFO    MainThread:27324 [wandb_run.py:_console_start():2377] atexit reg
2025-03-09 09:35:14,909 INFO    MainThread:27324 [wandb_run.py:_redirect():2227] redirect: wrap_raw
2025-03-09 09:35:14,929 INFO    MainThread:27324 [wandb_run.py:_redirect():2292] Wrapping output streams.
2025-03-09 09:35:14,930 INFO    MainThread:27324 [wandb_run.py:_redirect():2317] Redirects installed.
2025-03-09 09:35:14,957 INFO    MainThread:27324 [wandb_init.py:init():1037] run started, returning control to user process
2025-03-09 11:04:25,330 WARNING MsgRouterThr:27324 [router.py:message_loop():77] message_loop has been closed
Traceback (most recent call last):
  File "C:\Users\shrey\AppData\Roaming\Python\Python311\site-packages\wandb\sdk\lib\sock_client.py", line 258, in _read_packet_bytes
    data = self._sock.recv(self._bufsize)
           ^^^^^^^^^^^^^^^^^^^^^^^^^^^^^^
ConnectionResetError: [WinError 10054] An existing connection was forcibly closed by the remote host

The above exception was the direct cause of the following exception:

Traceback (most recent call last):
  File "C:\Users\shrey\AppData\Roaming\Python\Python311\site-packages\wandb\sdk\interface\router_sock.py", line 28, in _read_message
    resp = self._sock_client.read_server_response(timeout=1)
           ^^^^^^^^^^^^^^^^^^^^^^^^^^^^^^^^^^^^^^^^^^^^^^^^^
  File "C:\Users\shrey\AppData\Roaming\Python\Python311\site-packages\wandb\sdk\lib\sock_client.py", line 285, in read_server_response
    data = self._read_packet_bytes(timeout=timeout)
           ^^^^^^^^^^^^^^^^^^^^^^^^^^^^^^^^^^^^^^^^
  File "C:\Users\shrey\AppData\Roaming\Python\Python311\site-packages\wandb\sdk\lib\sock_client.py", line 262, in _read_packet_bytes
    raise SockClientClosedError from e
wandb.sdk.lib.sock_client.SockClientClosedError

The above exception was the direct cause of the following exception:

Traceback (most recent call last):
  File "C:\Users\shrey\AppData\Roaming\Python\Python311\site-packages\wandb\sdk\interface\router.py", line 70, in message_loop
    msg = self._read_message()
          ^^^^^^^^^^^^^^^^^^^^
  File "C:\Users\shrey\AppData\Roaming\Python\Python311\site-packages\wandb\sdk\interface\router_sock.py", line 30, in _read_message
    raise MessageRouterClosedError from e
wandb.sdk.interface.router.MessageRouterClosedError
2025-03-09 11:04:25,372 INFO    MsgRouterThr:27324 [mailbox.py:close():115] Closing mailbox, abandoning 2 handles.
