2025-03-10 07:44:50,395 INFO    MainThread:1964 [wandb_setup.py:_flush():67] Current SDK version is 0.19.7
2025-03-10 07:44:50,395 INFO    MainThread:1964 [wandb_setup.py:_flush():67] Configure stats pid to 1964
2025-03-10 07:44:50,395 INFO    MainThread:1964 [wandb_setup.py:_flush():67] Loading settings from C:\Users\shrey\.config\wandb\settings
2025-03-10 07:44:50,395 INFO    MainThread:1964 [wandb_setup.py:_flush():67] Loading settings from C:\Users\shrey\Desktop\ACAD\DL\DA6401_AS1\wandb\settings
2025-03-10 07:44:50,395 INFO    MainThread:1964 [wandb_setup.py:_flush():67] Loading settings from environment variables
2025-03-10 07:44:50,397 INFO    MainThread:1964 [wandb_init.py:setup_run_log_directory():647] Logging user logs to C:\Users\shrey\Desktop\ACAD\DL\DA6401_AS1\wandb\run-20250310_074450-xqjf06fx\logs\debug.log
2025-03-10 07:44:50,399 INFO    MainThread:1964 [wandb_init.py:setup_run_log_directory():648] Logging internal logs to C:\Users\shrey\Desktop\ACAD\DL\DA6401_AS1\wandb\run-20250310_074450-xqjf06fx\logs\debug-internal.log
2025-03-10 07:44:50,399 INFO    MainThread:1964 [wandb_init.py:init():761] calling init triggers
2025-03-10 07:44:50,400 INFO    MainThread:1964 [wandb_init.py:init():766] wandb.init called with sweep_config: {'activation': 'ReLU', 'batch_size': 16, 'beta': 0.04589134125879976, 'beta1': 0.9817501806261468, 'beta2': 0.9952633013104952, 'epochs': 10, 'epsilon': 8.574696579336792e-06, 'hidden_size': 32, 'learning_rate': 0.00023599310758409456, 'loss': 'mean_squared_error', 'momentum': 0.9081858521057236, 'num_layers': 6, 'optimizer': 'adam', 'weight_decay': 0.0005, 'weight_init': 'Xavier'}
config: {'_wandb': {}}
2025-03-10 07:44:50,400 INFO    MainThread:1964 [wandb_init.py:init():784] starting backend
2025-03-10 07:44:50,400 INFO    MainThread:1964 [wandb_init.py:init():788] sending inform_init request
2025-03-10 07:44:50,448 INFO    MainThread:1964 [backend.py:_multiprocessing_setup():97] multiprocessing start_methods=spawn, using: spawn
2025-03-10 07:44:50,454 INFO    MainThread:1964 [wandb_init.py:init():803] backend started and connected
2025-03-10 07:44:50,456 INFO    MainThread:1964 [wandb_run.py:_config_callback():1261] config_cb None None {'activation': 'ReLU', 'batch_size': 16, 'beta': 0.04589134125879976, 'beta1': 0.9817501806261468, 'beta2': 0.9952633013104952, 'epochs': 10, 'epsilon': 8.574696579336792e-06, 'hidden_size': 32, 'learning_rate': 0.00023599310758409456, 'loss': 'mean_squared_error', 'momentum': 0.9081858521057236, 'num_layers': 6, 'optimizer': 'adam', 'weight_decay': 0.0005, 'weight_init': 'Xavier'}
2025-03-10 07:44:50,458 INFO    MainThread:1964 [wandb_init.py:init():896] updated telemetry
2025-03-10 07:44:50,590 INFO    MainThread:1964 [wandb_init.py:init():920] communicating run to backend with 90.0 second timeout
2025-03-10 07:44:51,388 INFO    MainThread:1964 [wandb_init.py:init():995] starting run threads in backend
2025-03-10 07:44:54,553 INFO    MainThread:1964 [wandb_run.py:_console_start():2377] atexit reg
2025-03-10 07:44:54,553 INFO    MainThread:1964 [wandb_run.py:_redirect():2227] redirect: wrap_raw
2025-03-10 07:44:54,566 INFO    MainThread:1964 [wandb_run.py:_redirect():2292] Wrapping output streams.
2025-03-10 07:44:54,566 INFO    MainThread:1964 [wandb_run.py:_redirect():2317] Redirects installed.
2025-03-10 07:44:54,581 INFO    MainThread:1964 [wandb_init.py:init():1037] run started, returning control to user process
2025-03-10 07:53:19,076 WARNING MsgRouterThr:1964 [router.py:message_loop():77] message_loop has been closed
Traceback (most recent call last):
  File "C:\Users\shrey\AppData\Roaming\Python\Python311\site-packages\wandb\sdk\lib\sock_client.py", line 258, in _read_packet_bytes
    data = self._sock.recv(self._bufsize)
           ^^^^^^^^^^^^^^^^^^^^^^^^^^^^^^
ConnectionResetError: [WinError 10054] An existing connection was forcibly closed by the remote host

The above exception was the direct cause of the following exception:

Traceback (most recent call last):
  File "C:\Users\shrey\AppData\Roaming\Python\Python311\site-packages\wandb\sdk\interface\router_sock.py", line 28, in _read_message
    resp = self._sock_client.read_server_response(timeout=1)
           ^^^^^^^^^^^^^^^^^^^^^^^^^^^^^^^^^^^^^^^^^^^^^^^^^
  File "C:\Users\shrey\AppData\Roaming\Python\Python311\site-packages\wandb\sdk\lib\sock_client.py", line 285, in read_server_response
    data = self._read_packet_bytes(timeout=timeout)
           ^^^^^^^^^^^^^^^^^^^^^^^^^^^^^^^^^^^^^^^^
  File "C:\Users\shrey\AppData\Roaming\Python\Python311\site-packages\wandb\sdk\lib\sock_client.py", line 262, in _read_packet_bytes
    raise SockClientClosedError from e
wandb.sdk.lib.sock_client.SockClientClosedError

The above exception was the direct cause of the following exception:

Traceback (most recent call last):
  File "C:\Users\shrey\AppData\Roaming\Python\Python311\site-packages\wandb\sdk\interface\router.py", line 70, in message_loop
    msg = self._read_message()
          ^^^^^^^^^^^^^^^^^^^^
  File "C:\Users\shrey\AppData\Roaming\Python\Python311\site-packages\wandb\sdk\interface\router_sock.py", line 30, in _read_message
    raise MessageRouterClosedError from e
wandb.sdk.interface.router.MessageRouterClosedError
2025-03-10 07:53:19,080 INFO    MsgRouterThr:1964 [mailbox.py:close():115] Closing mailbox, abandoning 2 handles.
