2025-03-09 01:54:52,299 INFO    MainThread:17568 [wandb_setup.py:_flush():67] Current SDK version is 0.19.7
2025-03-09 01:54:52,299 INFO    MainThread:17568 [wandb_setup.py:_flush():67] Configure stats pid to 17568
2025-03-09 01:54:52,299 INFO    MainThread:17568 [wandb_setup.py:_flush():67] Loading settings from C:\Users\shrey\.config\wandb\settings
2025-03-09 01:54:52,300 INFO    MainThread:17568 [wandb_setup.py:_flush():67] Loading settings from C:\Users\shrey\Desktop\ACAD\DL\DA6401_AS1\wandb\settings
2025-03-09 01:54:52,301 INFO    MainThread:17568 [wandb_setup.py:_flush():67] Loading settings from environment variables
2025-03-09 01:54:52,303 INFO    MainThread:17568 [wandb_init.py:setup_run_log_directory():647] Logging user logs to C:\Users\shrey\Desktop\ACAD\DL\DA6401_AS1\wandb\run-20250309_015452-1pi6tmz6\logs\debug.log
2025-03-09 01:54:52,304 INFO    MainThread:17568 [wandb_init.py:setup_run_log_directory():648] Logging internal logs to C:\Users\shrey\Desktop\ACAD\DL\DA6401_AS1\wandb\run-20250309_015452-1pi6tmz6\logs\debug-internal.log
2025-03-09 01:54:52,305 INFO    MainThread:17568 [wandb_init.py:init():761] calling init triggers
2025-03-09 01:54:52,305 INFO    MainThread:17568 [wandb_init.py:init():766] wandb.init called with sweep_config: {'activation': 'ReLU', 'batch_size': 64, 'beta': 0.5, 'beta1': 0.9, 'beta2': 0.999, 'epochs': 5, 'epsilon': 1e-06, 'hidden_size': 32, 'learning_rate': 0.0001, 'loss': 'cross_entropy', 'momentum': 0.9, 'num_layers': 5, 'optimizer': 'nadam', 'weight_decay': 0, 'weight_init': 'Xavier'}
config: {'_wandb': {}}
2025-03-09 01:54:52,305 INFO    MainThread:17568 [wandb_init.py:init():784] starting backend
2025-03-09 01:54:52,305 INFO    MainThread:17568 [wandb_init.py:init():788] sending inform_init request
2025-03-09 01:54:52,360 INFO    MainThread:17568 [backend.py:_multiprocessing_setup():97] multiprocessing start_methods=spawn, using: spawn
2025-03-09 01:54:52,370 INFO    MainThread:17568 [wandb_init.py:init():803] backend started and connected
2025-03-09 01:54:52,372 INFO    MainThread:17568 [wandb_run.py:_config_callback():1261] config_cb None None {'activation': 'ReLU', 'batch_size': 64, 'beta': 0.5, 'beta1': 0.9, 'beta2': 0.999, 'epochs': 5, 'epsilon': 1e-06, 'hidden_size': 32, 'learning_rate': 0.0001, 'loss': 'cross_entropy', 'momentum': 0.9, 'num_layers': 5, 'optimizer': 'nadam', 'weight_decay': 0, 'weight_init': 'Xavier'}
2025-03-09 01:54:52,374 INFO    MainThread:17568 [wandb_init.py:init():896] updated telemetry
2025-03-09 01:54:52,594 INFO    MainThread:17568 [wandb_init.py:init():920] communicating run to backend with 90.0 second timeout
2025-03-09 01:54:54,150 INFO    MainThread:17568 [wandb_init.py:init():995] starting run threads in backend
2025-03-09 01:54:55,910 INFO    MainThread:17568 [wandb_run.py:_console_start():2377] atexit reg
2025-03-09 01:54:55,910 INFO    MainThread:17568 [wandb_run.py:_redirect():2227] redirect: wrap_raw
2025-03-09 01:54:55,911 INFO    MainThread:17568 [wandb_run.py:_redirect():2292] Wrapping output streams.
2025-03-09 01:54:55,911 INFO    MainThread:17568 [wandb_run.py:_redirect():2317] Redirects installed.
2025-03-09 01:54:55,922 INFO    MainThread:17568 [wandb_init.py:init():1037] run started, returning control to user process
2025-03-09 02:00:33,330 WARNING MsgRouterThr:17568 [router.py:message_loop():77] message_loop has been closed
Traceback (most recent call last):
  File "C:\Users\shrey\AppData\Roaming\Python\Python311\site-packages\wandb\sdk\interface\router_sock.py", line 28, in _read_message
    resp = self._sock_client.read_server_response(timeout=1)
           ^^^^^^^^^^^^^^^^^^^^^^^^^^^^^^^^^^^^^^^^^^^^^^^^^
  File "C:\Users\shrey\AppData\Roaming\Python\Python311\site-packages\wandb\sdk\lib\sock_client.py", line 285, in read_server_response
    data = self._read_packet_bytes(timeout=timeout)
           ^^^^^^^^^^^^^^^^^^^^^^^^^^^^^^^^^^^^^^^^
  File "C:\Users\shrey\AppData\Roaming\Python\Python311\site-packages\wandb\sdk\lib\sock_client.py", line 270, in _read_packet_bytes
    raise SockClientClosedError
wandb.sdk.lib.sock_client.SockClientClosedError

The above exception was the direct cause of the following exception:

Traceback (most recent call last):
  File "C:\Users\shrey\AppData\Roaming\Python\Python311\site-packages\wandb\sdk\interface\router.py", line 70, in message_loop
    msg = self._read_message()
          ^^^^^^^^^^^^^^^^^^^^
  File "C:\Users\shrey\AppData\Roaming\Python\Python311\site-packages\wandb\sdk\interface\router_sock.py", line 30, in _read_message
    raise MessageRouterClosedError from e
wandb.sdk.interface.router.MessageRouterClosedError
2025-03-09 02:00:33,342 INFO    MsgRouterThr:17568 [mailbox.py:close():115] Closing mailbox, abandoning 1 handles.
