2025-03-09 00:29:27,455 INFO    MainThread:22180 [wandb_setup.py:_flush():67] Current SDK version is 0.19.7
2025-03-09 00:29:27,455 INFO    MainThread:22180 [wandb_setup.py:_flush():67] Configure stats pid to 22180
2025-03-09 00:29:27,455 INFO    MainThread:22180 [wandb_setup.py:_flush():67] Loading settings from C:\Users\shrey\.config\wandb\settings
2025-03-09 00:29:27,455 INFO    MainThread:22180 [wandb_setup.py:_flush():67] Loading settings from C:\Users\shrey\Desktop\ACAD\DL\DA6401_AS1\wandb\settings
2025-03-09 00:29:27,455 INFO    MainThread:22180 [wandb_setup.py:_flush():67] Loading settings from environment variables
2025-03-09 00:29:27,456 INFO    MainThread:22180 [wandb_init.py:setup_run_log_directory():647] Logging user logs to C:\Users\shrey\Desktop\ACAD\DL\DA6401_AS1\wandb\run-20250309_002927-8dwh1kf0\logs\debug.log
2025-03-09 00:29:27,459 INFO    MainThread:22180 [wandb_init.py:setup_run_log_directory():648] Logging internal logs to C:\Users\shrey\Desktop\ACAD\DL\DA6401_AS1\wandb\run-20250309_002927-8dwh1kf0\logs\debug-internal.log
2025-03-09 00:29:27,459 INFO    MainThread:22180 [wandb_init.py:init():761] calling init triggers
2025-03-09 00:29:27,460 INFO    MainThread:22180 [wandb_init.py:init():766] wandb.init called with sweep_config: {'activation': 'sigmoid', 'batch_size': 16, 'beta': 0.95, 'beta1': 0.8, 'beta2': 0.9, 'epochs': 15, 'epsilon': 1e-05, 'hidden_size': 64, 'learning_rate': 0.001, 'loss': 'cross_entropy', 'momentum': 0.5, 'num_layers': 6, 'optimizer': 'sgd', 'weight_decay': 0.5, 'weight_init': 'random'}
config: {'_wandb': {}}
2025-03-09 00:29:27,460 INFO    MainThread:22180 [wandb_init.py:init():784] starting backend
2025-03-09 00:29:27,460 INFO    MainThread:22180 [wandb_init.py:init():788] sending inform_init request
2025-03-09 00:29:27,511 INFO    MainThread:22180 [backend.py:_multiprocessing_setup():97] multiprocessing start_methods=spawn, using: spawn
2025-03-09 00:29:27,512 INFO    MainThread:22180 [wandb_init.py:init():803] backend started and connected
2025-03-09 00:29:27,514 INFO    MainThread:22180 [wandb_run.py:_config_callback():1261] config_cb None None {'activation': 'sigmoid', 'batch_size': 16, 'beta': 0.95, 'beta1': 0.8, 'beta2': 0.9, 'epochs': 15, 'epsilon': 1e-05, 'hidden_size': 64, 'learning_rate': 0.001, 'loss': 'cross_entropy', 'momentum': 0.5, 'num_layers': 6, 'optimizer': 'sgd', 'weight_decay': 0.5, 'weight_init': 'random'}
2025-03-09 00:29:27,516 INFO    MainThread:22180 [wandb_init.py:init():896] updated telemetry
2025-03-09 00:29:27,631 INFO    MainThread:22180 [wandb_init.py:init():920] communicating run to backend with 90.0 second timeout
2025-03-09 00:29:29,097 INFO    MainThread:22180 [wandb_init.py:init():995] starting run threads in backend
2025-03-09 00:29:29,815 INFO    MainThread:22180 [wandb_run.py:_console_start():2377] atexit reg
2025-03-09 00:29:29,815 INFO    MainThread:22180 [wandb_run.py:_redirect():2227] redirect: wrap_raw
2025-03-09 00:29:29,816 INFO    MainThread:22180 [wandb_run.py:_redirect():2292] Wrapping output streams.
2025-03-09 00:29:29,816 INFO    MainThread:22180 [wandb_run.py:_redirect():2317] Redirects installed.
2025-03-09 00:29:29,823 INFO    MainThread:22180 [wandb_init.py:init():1037] run started, returning control to user process
2025-03-09 01:19:19,838 WARNING MsgRouterThr:22180 [router.py:message_loop():77] message_loop has been closed
Traceback (most recent call last):
  File "C:\Users\shrey\AppData\Roaming\Python\Python311\site-packages\wandb\sdk\interface\router_sock.py", line 28, in _read_message
    resp = self._sock_client.read_server_response(timeout=1)
           ^^^^^^^^^^^^^^^^^^^^^^^^^^^^^^^^^^^^^^^^^^^^^^^^^
  File "C:\Users\shrey\AppData\Roaming\Python\Python311\site-packages\wandb\sdk\lib\sock_client.py", line 285, in read_server_response
    data = self._read_packet_bytes(timeout=timeout)
           ^^^^^^^^^^^^^^^^^^^^^^^^^^^^^^^^^^^^^^^^
  File "C:\Users\shrey\AppData\Roaming\Python\Python311\site-packages\wandb\sdk\lib\sock_client.py", line 270, in _read_packet_bytes
    raise SockClientClosedError
wandb.sdk.lib.sock_client.SockClientClosedError

The above exception was the direct cause of the following exception:

Traceback (most recent call last):
  File "C:\Users\shrey\AppData\Roaming\Python\Python311\site-packages\wandb\sdk\interface\router.py", line 70, in message_loop
    msg = self._read_message()
          ^^^^^^^^^^^^^^^^^^^^
  File "C:\Users\shrey\AppData\Roaming\Python\Python311\site-packages\wandb\sdk\interface\router_sock.py", line 30, in _read_message
    raise MessageRouterClosedError from e
wandb.sdk.interface.router.MessageRouterClosedError
2025-03-09 01:19:20,147 INFO    MsgRouterThr:22180 [mailbox.py:close():115] Closing mailbox, abandoning 1 handles.
