2025-03-09 07:28:56,228 INFO    MainThread:13928 [wandb_setup.py:_flush():67] Current SDK version is 0.19.7
2025-03-09 07:28:56,228 INFO    MainThread:13928 [wandb_setup.py:_flush():67] Configure stats pid to 13928
2025-03-09 07:28:56,228 INFO    MainThread:13928 [wandb_setup.py:_flush():67] Loading settings from C:\Users\shrey\.config\wandb\settings
2025-03-09 07:28:56,230 INFO    MainThread:13928 [wandb_setup.py:_flush():67] Loading settings from C:\Users\shrey\Desktop\ACAD\DL\DA6401_AS1\wandb\settings
2025-03-09 07:28:56,230 INFO    MainThread:13928 [wandb_setup.py:_flush():67] Loading settings from environment variables
2025-03-09 07:28:56,230 INFO    MainThread:13928 [wandb_init.py:setup_run_log_directory():647] Logging user logs to C:\Users\shrey\Desktop\ACAD\DL\DA6401_AS1\wandb\run-20250309_072856-wzvy8si5\logs\debug.log
2025-03-09 07:28:56,247 INFO    MainThread:13928 [wandb_init.py:setup_run_log_directory():648] Logging internal logs to C:\Users\shrey\Desktop\ACAD\DL\DA6401_AS1\wandb\run-20250309_072856-wzvy8si5\logs\debug-internal.log
2025-03-09 07:28:56,248 INFO    MainThread:13928 [wandb_init.py:init():761] calling init triggers
2025-03-09 07:28:56,248 INFO    MainThread:13928 [wandb_init.py:init():766] wandb.init called with sweep_config: {'activation': 'ReLU', 'batch_size': 32, 'beta': 0.07431275333417509, 'beta1': 0.9888491530042852, 'beta2': 0.9958043043024656, 'epochs': 15, 'epsilon': 7.543464665471729e-06, 'hidden_size': 128, 'learning_rate': 0.00032959494515422594, 'loss': 'cross_entropy', 'momentum': 0.9217362993530512, 'num_layers': 3, 'optimizer': 'nag', 'weight_decay': 0.001, 'weight_init': 'Xavier'}
config: {'_wandb': {}}
2025-03-09 07:28:56,248 INFO    MainThread:13928 [wandb_init.py:init():784] starting backend
2025-03-09 07:28:56,248 INFO    MainThread:13928 [wandb_init.py:init():788] sending inform_init request
2025-03-09 07:28:56,348 INFO    MainThread:13928 [backend.py:_multiprocessing_setup():97] multiprocessing start_methods=spawn, using: spawn
2025-03-09 07:28:56,357 INFO    MainThread:13928 [wandb_init.py:init():803] backend started and connected
2025-03-09 07:28:56,359 INFO    MainThread:13928 [wandb_run.py:_config_callback():1261] config_cb None None {'activation': 'ReLU', 'batch_size': 32, 'beta': 0.07431275333417509, 'beta1': 0.9888491530042852, 'beta2': 0.9958043043024656, 'epochs': 15, 'epsilon': 7.543464665471729e-06, 'hidden_size': 128, 'learning_rate': 0.00032959494515422594, 'loss': 'cross_entropy', 'momentum': 0.9217362993530512, 'num_layers': 3, 'optimizer': 'nag', 'weight_decay': 0.001, 'weight_init': 'Xavier'}
2025-03-09 07:28:56,361 INFO    MainThread:13928 [wandb_init.py:init():896] updated telemetry
2025-03-09 07:28:56,620 INFO    MainThread:13928 [wandb_init.py:init():920] communicating run to backend with 90.0 second timeout
2025-03-09 07:28:57,353 INFO    MainThread:13928 [wandb_init.py:init():995] starting run threads in backend
2025-03-09 07:29:00,618 INFO    MainThread:13928 [wandb_run.py:_console_start():2377] atexit reg
2025-03-09 07:29:00,620 INFO    MainThread:13928 [wandb_run.py:_redirect():2227] redirect: wrap_raw
2025-03-09 07:29:00,698 INFO    MainThread:13928 [wandb_run.py:_redirect():2292] Wrapping output streams.
2025-03-09 07:29:00,698 INFO    MainThread:13928 [wandb_run.py:_redirect():2317] Redirects installed.
2025-03-09 07:29:00,724 INFO    MainThread:13928 [wandb_init.py:init():1037] run started, returning control to user process
2025-03-09 08:24:50,377 WARNING MsgRouterThr:13928 [router.py:message_loop():77] message_loop has been closed
Traceback (most recent call last):
  File "C:\Users\shrey\AppData\Roaming\Python\Python311\site-packages\wandb\sdk\lib\sock_client.py", line 258, in _read_packet_bytes
    data = self._sock.recv(self._bufsize)
           ^^^^^^^^^^^^^^^^^^^^^^^^^^^^^^
ConnectionResetError: [WinError 10054] An existing connection was forcibly closed by the remote host

The above exception was the direct cause of the following exception:

Traceback (most recent call last):
  File "C:\Users\shrey\AppData\Roaming\Python\Python311\site-packages\wandb\sdk\interface\router_sock.py", line 28, in _read_message
    resp = self._sock_client.read_server_response(timeout=1)
           ^^^^^^^^^^^^^^^^^^^^^^^^^^^^^^^^^^^^^^^^^^^^^^^^^
  File "C:\Users\shrey\AppData\Roaming\Python\Python311\site-packages\wandb\sdk\lib\sock_client.py", line 285, in read_server_response
    data = self._read_packet_bytes(timeout=timeout)
           ^^^^^^^^^^^^^^^^^^^^^^^^^^^^^^^^^^^^^^^^
  File "C:\Users\shrey\AppData\Roaming\Python\Python311\site-packages\wandb\sdk\lib\sock_client.py", line 262, in _read_packet_bytes
    raise SockClientClosedError from e
wandb.sdk.lib.sock_client.SockClientClosedError

The above exception was the direct cause of the following exception:

Traceback (most recent call last):
  File "C:\Users\shrey\AppData\Roaming\Python\Python311\site-packages\wandb\sdk\interface\router.py", line 70, in message_loop
    msg = self._read_message()
          ^^^^^^^^^^^^^^^^^^^^
  File "C:\Users\shrey\AppData\Roaming\Python\Python311\site-packages\wandb\sdk\interface\router_sock.py", line 30, in _read_message
    raise MessageRouterClosedError from e
wandb.sdk.interface.router.MessageRouterClosedError
2025-03-09 08:24:50,381 INFO    MsgRouterThr:13928 [mailbox.py:close():115] Closing mailbox, abandoning 3 handles.
